Workbook

Sheet Допущения
A1: Допущения финмодели QuipQuill — все входные данные (синие ячейки можно менять)
A2: Синий — ввод, чёрный — формула, зелёный — ссылка на другой лист. Валюта модели — USD. Дата расчёта: 17.10.2026. Месяц 1 модели = ноябрь 2026.
A4: Параметр | B4: Ед. | C4: Пессим. | D4: Базовый | E4: Оптим. | F4: Источник / обоснование
A6: Общие
A7: Курс RUB за 1 USD | B7: ₽ | C7: =$D$7 | D7: 83 | E7: =$D$7 | F7: ЦБ РФ / рынок, окт. 2026 ≈ 83 (диапазон 2026: 71–86). Пересчитать на дату вложения
A8: Курс GEL за 1 USD | B8: ₾ | C8: =$D$8 | D8: 2.65 | E8: =$D$8 | F8: НБГ, 2026 ≈ 2,62–2,70
A9: Месяц выхода MVP в магазины | B9: мес. | C9: 6 | D9: 5 | E9: 4 | F9: Цель пользователя: 3–6 мес. Месяц 5 = март 2027
A10: Месяц регистрации ООО | B10: мес. | C10: =$D$10 | D10: 2 | E10: =$D$10 | F10: Декабрь 2026: до подачи в магазины (D-U-N-S для Apple/Google)
A12: Цены моделей OpenRouter, $ за 1 млн токенов
A13: Haiku 5.5 — вход | B13: $/1M | C13: =$D$13 | D13: 0.1 | E13: =$D$13 | F13: openrouter.ai/api/v1/models, 17.10.2026 (до 100K токенов контекста)
A14: Haiku 5.5 — выход | B14: $/1M | C14: =$D$14 | D14: 0.5 | E14: =$D$14 | F14: там же
A15: Haiku 5.5 — чтение кэша | B15: $/1M | C15: =$D$15 | D15: 0.01 | E15: =$D$15 | F15: там же
A16: Haiku 5.5 — запись кэша | B16: $/1M | C16: =$D$16 | D16: 0.125 | E16: =$D$16 | F16: там же
A17: Sonnet 5.5 — вход | B17: $/1M | C17: =$D$17 | D17: 2 | E17: =$D$17 | F17: там же
A18: Sonnet 5.5 — выход | B18: $/1M | C18: =$D$18 | D18: 10 | E18: =$D$18 | F18: там же
A19: Sonnet 5.5 — чтение кэша | B19: $/1M | C19: =$D$19 | D19: 0.1 | E19: =$D$19 | F19: там же
A20: Sonnet 5.5 — запись кэша | B20: $/1M | C20: =$D$20 | D20: 2.5 | E20: =$D$20 | F20: там же
A22: Профиль хода (из тестов 6.2i: 12 ходов игрока, 2 прогона)
A23: Некэшированный вход за ход | B23: ток. | C23: =$D$23 | D23: 9800 | E23: =$D$23 | F23: Среднее: 29,5K вход − 19,7K из кэша
A24: Вход из кэша за ход | B24: ток. | C24: =$D$24 | D24: 19700 | E24: =$D$24 | F24: Среднее по 12 ходам
A25: Выход за ход | B25: ток. | C25: =$D$25 | D25: 1310 | E25: =$D$25 | F25: Среднее по 12 ходам
A26: Доля некэш. входа, идущая в запись кэша | B26: доля | C26: =$D$26 | D26: 0.15 | E26: =$D$26 | F26: Подбор: модель даёт $0,00187 при фактическом среднем $0,00186
A27: Доля токенов хода у мастера (gm) | B27: доля | C27: =$D$27 | D27: 0.65 | E27: =$D$27 | F27: Оценка: gm — 3 из ~6 вызовов, но самые длинные промпты
A28: Множитель длинных сессий (рост контекста, повторы) | B28: x | C28: 1.5 | D28: 1.3 | E28: 1.15 | F28: Ходы в тестах дорожали с $0,0011 до $0,0028 за 7 ходов; запас на сводки и повторы
A29: Модерация на ход (Llama Guard 4 / перехват кризиса) | B29: $ | C29: 0.0003 | D29: 0.0002 | E29: 0.0001 | F29: Llama Guard 4: $0,18/1M; ~1–1,5K токенов на проверку ввода и выборочно ответа
A31: Тарифы (цены — в магазинах, без налога с продаж США)
A32: Free: ходов в неделю | B32: ходов | C32: =$D$32 | D32: 30 | E32: =$D$32 | F32: ≈ одна сессия в неделю; дешёвая воронка
A33: Комфорт: ходов за сессию | B33: ходов | C33: =$D$33 | D33: 45 | E33: =$D$33 | F33: ~45–60 мин игры, 1 ход ≈ 1–1,3 мин с чтением
A34: Комфорт: сессий в неделю | B34: сессий | C34: =$D$34 | D34: 6 | E34: =$D$34 | F34: Активный игрок: почти ежедневно
A35: Teen 13–17 (строгий режим): цена | B35: $/мес | C35: =$D$35 | D35: 4.99 | E35: =$D$35 | F35: Дешёвый тариф для школьников (идея пользователя)
A36: Teen: ходов в месяц | B36: ходов | C36: =$D$36 | D36: 600 | E36: =$D$36 | F36: ½ комфортного объёма
A37: Standard: цена | B37: $/мес | C37: =$D$37 | D37: 9.99 | E37: =$D$37 | F37: Рынок: c.ai+ $9,99; AI Dungeon $9,99; NovelAI $10
A38: Standard: ходов в месяц | B38: ходов | C38: =$D$38 | D38: 1200 | E38: =$D$38 | F38: Комфортный объём (см. «Себестоимость»)
A39: Premium (мастер на Sonnet): цена | B39: $/мес | C39: =$D$39 | D39: 19.99 | E39: =$D$39 | F39: Рынок: NovelAI Opus $25; Friends & Fables $19,95–39,95
A40: Premium: ходов в месяц, всего | B40: ходов | C40: =$D$40 | D40: 1200 | E40: =$D$40 | F40: Комфортный объём
A41: Premium: из них ходов на Sonnet | B41: ходов | C41: =$D$41 | D41: 300 | E41: =$D$41 | F41: Остальные — на Haiku
A42: Legend (10 000 ходов): цена | B42: $/мес | C42: =$D$42 | D42: 39.99 | E42: =$D$42 | F42: Для энтузиастов; см. расчёт маржи
A43: Legend: ходов в месяц | B43: ходов | C43: =$D$43 | D43: 10000 | E43: =$D$43 | F43: Запрошенный объём
A44: Доля платящих: Teen | B44: доля | C44: =$D$44 | D44: 0.15 | E44: =$D$44 | F44: Оценка
A45: Доля платящих: Standard | B45: доля | C45: =$D$45 | D45: 0.6 | E45: =$D$45 | F45: Оценка
...

Sheet Сценарии
A1: Сводка по сценариям
A3: Показатель | B3: Пессим. | C3: Базовый | D3: Оптим.
A4: Выход MVP (месяц №) | B4: ='Допущения'!$C$9 | C4: ='Допущения'!$D$9 | D4: ='Допущения'!$E$9
A5: Первый месяц с EBITDA ≥ 0 (№) | B5: ='Модель_П'!$B$68 | C5: ='Модель_Б'!$B$68 | D5: ='Модель_О'!$B$68
A6: Устойчивая безубыточность: EBITDA ≥ 0 и дальше (№ мес.) | B6: ='Модель_П'!$B$69 | C6: ='Модель_Б'!$B$69 | D6: ='Модель_О'!$B$69
A7: Устойчивая безубыточность (дата) | B7: ='Модель_П'!$B$70 | C7: ='Модель_Б'!$B$70 | D7: ='Модель_О'!$B$70
A8: Окупаемость: накопленный поток ≥ 0 (№ мес.) | B8: ='Модель_П'!$B$71 | C8: ='Модель_Б'!$B$71 | D8: ='Модель_О'!$B$71
A9: Пиковая потребность в финансировании, $ | B9: ='Модель_П'!$B$72 | C9: ='Модель_Б'!$B$72 | D9: ='Модель_О'!$B$72
A10: То же, ₽ | B10: ='Модель_П'!$B$73 | C10: ='Модель_Б'!$B$73 | D10: ='Модель_О'!$B$73
A11: Чистая выручка, год 1, $ | B11: ='Модель_П'!$B$74 | C11: ='Модель_Б'!$B$74 | D11: ='Модель_О'!$B$74
A12: Чистая выручка, год 2, $ | B12: ='Модель_П'!$B$75 | C12: ='Модель_Б'!$B$75 | D12: ='Модель_О'!$B$75
A13: Чистая выручка, год 3, $ | B13: ='Модель_П'!$B$76 | C13: ='Модель_Б'!$B$76 | D13: ='Модель_О'!$B$76
A14: EBITDA, год 1, $ | B14: ='Модель_П'!$B$77 | C14: ='Модель_Б'!$B$77 | D14: ='Модель_О'!$B$77
A15: EBITDA, год 2, $ | B15: ='Модель_П'!$B$78 | C15: ='Модель_Б'!$B$78 | D15: ='Модель_О'!$B$78
A16: EBITDA, год 3, $ | B16: ='Модель_П'!$B$79 | C16: ='Модель_Б'!$B$79 | D16: ='Модель_О'!$B$79
A17: Активные, мес. 12 | B17: ='Модель_П'!$B$83 | C17: ='Модель_Б'!$B$83 | D17: ='Модель_О'!$B$83
A18: Активные, мес. 36 | B18: ='Модель_П'!$B$84 | C18: ='Модель_Б'!$B$84 | D18: ='Модель_О'!$B$84
A19: Платящие, мес. 12 | B19: ='Модель_П'!$B$80 | C19: ='Модель_Б'!$B$80 | D19: ='Модель_О'!$B$80
A20: Платящие, мес. 24 | B20: ='Модель_П'!$B$81 | C20: ='Модель_Б'!$B$81 | D20: ='Модель_О'!$B$81
A21: Платящие, мес. 36 | B21: ='Модель_П'!$B$82 | C21: ='Модель_Б'!$B$82 | D21: ='Модель_О'!$B$82
A22: MRR, мес. 12, $ | B22: ='Модель_П'!$B$85 | C22: ='Модель_Б'!$B$85 | D22: ='Модель_О'!$B$85
A23: MRR, мес. 24, $ | B23: ='Модель_П'!$B$86 | C23: ='Модель_Б'!$B$86 | D23: ='Модель_О'!$B$86
A24: MRR, мес. 36, $ | B24: ='Модель_П'!$B$87 | C24: ='Модель_Б'!$B$87 | D24: ='Модель_О'!$B$87
A25: ARR, мес. 36, $ | B25: ='Модель_П'!$B$88 | C25: ='Модель_Б'!$B$88 | D25: ='Модель_О'!$B$88
A26: CAC средний (маркетинг / новые платящие после выхода), $ | B26: ='Модель_П'!$B$89 | C26: ='Модель_Б'!$B$89 | D26: ='Модель_О'!$B$89
A27: LTV платящего (чистая выручка × маржа / отток), $ | B27: ='Модель_П'!$B$90 | C27: ='Модель_Б'!$B$90 | D27: ='Модель_О'!$B$90
A28: LTV / CAC | B28: ='Модель_П'!$B$91 | C28: ='Модель_Б'!$B$91 | D28: ='Модель_О'!$B$91
A29: Валовая маржа за 36 мес. | B29: ='Модель_П'!$B$92 | C29: ='Модель_Б'!$B$92 | D29: ='Модель_О'!$B$92
A30: NPV операционного потока + терминальная стоимость, $ | B30: ='Модель_П'!$B$93 | C30: ='Модель_Б'!$B$93 | D30: ='Модель_О'!$B$93
A31: IRR годовая | B31: ='Модель_П'!$B$94 | C31: ='Модель_Б'!$B$94 | D31: ='Модель_О'!$B$94
A32: Мин. касса: вариант 1, $ | B32: ='Модель_П'!$B$96 | C32: ='Модель_Б'!$B$96 | D32: ='Модель_О'!$B$96
A33: Мин. касса: вариант 2, $ | B33: ='Модель_П'!$B$97 | C33: ='Модель_Б'!$B$97 | D33: ='Модель_О'!$B$97
A34: Мин. касса: вариант 3, $ | B34: ='Модель_П'!$B$98 | C34: ='Модель_Б'!$B$98 | D34: ='Модель_О'!$B$98
A36: Касса на конец месяца, $ (выбранный вариант вложений) — для графика
A37: Месяц | B37: Пессимистичный | C37: Базовый | D37: Оптимистичный
A38: 1 | B38: ='Модель_П'!C55 | C38: ='Модель_Б'!C55 | D38: ='Модель_О'!C55
A39: 2 | B39: ='Модель_П'!D55 | C39: ='Модель_Б'!D55 | D39: ='Модель_О'!D55
A40: 3 | B40: ='Модель_П'!E55 | C40: ='Модель_Б'!E55 | D40: ='Модель_О'!E55
A41: 4 | B41: ='Модель_П'!F55 | C41: ='Модель_Б'!F55 | D41: ='Модель_О'!F55
A42: 5 | B42: ='Модель_П'!G55 | C42: ='Модель_Б'!G55 | D42: ='Модель_О'!G55
...

Sheet Себестоимость
A1: Себестоимость хода, лимиты и цена подписки
A2: «Запрос» = ход игрока: все вызовы guard + gm + npc + generator за одну реплику. Колонки C–E — сценарии.
A4: Показатель | B4: Ед. | C4: Пессим. | D4: Базовый | E4: Оптим. | F4: Формула / комментарий
A5: Ход на Haiku, токены теста | B5: $ | C5: =('Допущения'!$C$23*(1-'Допущения'!$C$26)*'Допущения'!$C$13+'Допущения'!$C$23*'Допущения'!$C$26*'Допущения'!$C$16+'Допущения'!$C$24*'Допущения'!$C$15+'Допущения'!$C$25*'Допущения'!$C$14)/1000000 | D5: =('Допущения'!$D$23*(1-'Допущения'!$D$26)*'Допущения'!$D$13+'Допущения'!$D$23*'Допущения'!$D$26*'Допущения'!$D$16+'Допущения'!$D$24*'Допущения'!$D$15+'Допущения'!$D$25*'Допущения'!$D$14)/1000000 | E5: =('Допущения'!$E$23*(1-'Допущения'!$E$26)*'Допущения'!$E$13+'Допущения'!$E$23*'Допущения'!$E$26*'Допущения'!$E$16+'Допущения'!$E$24*'Допущения'!$E$15+'Допущения'!$E$25*'Допущения'!$E$14)/1000000 | F5: Проверка: фактическое среднее по тестам $0,00186
A6: Тот же ход целиком на Sonnet | B6: $ | C6: =('Допущения'!$C$23*(1-'Допущения'!$C$26)*'Допущения'!$C$17+'Допущения'!$C$23*'Допущения'!$C$26*'Допущения'!$C$20+'Допущения'!$C$24*'Допущения'!$C$19+'Допущения'!$C$25*'Допущения'!$C$18)/1000000 | D6: =('Допущения'!$D$23*(1-'Допущения'!$D$26)*'Допущения'!$D$17+'Допущения'!$D$23*'Допущения'!$D$26*'Допущения'!$D$20+'Допущения'!$D$24*'Допущения'!$D$19+'Допущения'!$D$25*'Допущения'!$D$18)/1000000 | E6: =('Допущения'!$E$23*(1-'Допущения'!$E$26)*'Допущения'!$E$17+'Допущения'!$E$23*'Допущения'!$E$26*'Допущения'!$E$20+'Допущения'!$E$24*'Допущения'!$E$19+'Допущения'!$E$25*'Допущения'!$E$18)/1000000 | F6: Справочно: в Premium на Sonnet только мастер
A7: Себестоимость хода Haiku (с запасом и модерацией) | B7: $ | C7: =$C$5*'Допущения'!$C$28+'Допущения'!$C$29 | D7: =$D$5*'Допущения'!$D$28+'Допущения'!$D$29 | E7: =$E$5*'Допущения'!$E$28+'Допущения'!$E$29 | F7: × множитель длинных сессий + модерация
A8: Себестоимость хода Premium (мастер на Sonnet, прочие — Haiku) | B8: $ | C8: =('Допущения'!$C$27*$C$6+(1-'Допущения'!$C$27)*$C$5)*'Допущения'!$C$28+'Допущения'!$C$29 | D8: =('Допущения'!$D$27*$D$6+(1-'Допущения'!$D$27)*$D$5)*'Допущения'!$D$28+'Допущения'!$D$29 | E8: =('Допущения'!$E$27*$E$6+(1-'Допущения'!$E$27)*$E$5)*'Допущения'!$E$28+'Допущения'!$E$29
A9: Premium-ход дороже Haiku-хода в | B9: x | C9: =$C$8/$C$7 | D9: =$D$8/$D$7 | E9: =$E$8/$E$7
A10: Чистыми с $1 цены (после магазинов, Paddle %, НДС) | B10: доля | C10: =(1-'Допущения'!$C$56)*((1-'Допущения'!$C$53)*(1-'Допущения'!$C$52)+'Допущения'!$C$53*(1-'Допущения'!$C$54)) | D10: =(1-'Допущения'!$D$56)*((1-'Допущения'!$D$53)*(1-'Допущения'!$D$52)+'Допущения'!$D$53*(1-'Допущения'!$D$54)) | E10: =(1-'Допущения'!$E$56)*((1-'Допущения'!$E$53)*(1-'Допущения'!$E$52)+'Допущения'!$E$53*(1-'Допущения'!$E$54)) | F10: Фикс. $0,50 Paddle вычитается отдельно
A11: Комфортный объём, ходов в месяц | B11: ходов | C11: =ROUNDUP('Допущения'!$C$33*'Допущения'!$C$34*52/12/100,0)*100 | D11: =ROUNDUP('Допущения'!$D$33*'Допущения'!$D$34*52/12/100,0)*100 | E11: =ROUNDUP('Допущения'!$E$33*'Допущения'!$E$34*52/12/100,0)*100 | F11: сессия × сессий в неделю × 4,33, вверх до сотни
A12: ARPPU брутто (средневзвешенная цена) | B12: $ | C12: ='Допущения'!$C$44*'Допущения'!$C$35+'Допущения'!$C$45*'Допущения'!$C$37+'Допущения'!$C$46*'Допущения'!$C$39+'Допущения'!$C$47*'Допущения'!$C$42 | D12: ='Допущения'!$D$44*'Допущения'!$D$35+'Допущения'!$D$45*'Допущения'!$D$37+'Допущения'!$D$46*'Допущения'!$D$39+'Допущения'!$D$47*'Допущения'!$D$42 | E12: ='Допущения'!$E$44*'Допущения'!$E$35+'Допущения'!$E$45*'Допущения'!$E$37+'Допущения'!$E$46*'Допущения'!$E$39+'Допущения'!$E$47*'Допущения'!$E$42 | F12: Σ доля × цена
A13: Чистая выручка на платящего | B13: $ | C13: ='Допущения'!$C$44*('Допущения'!$C$35*$C$10-'Допущения'!$C$53*'Допущения'!$C$55)+'Допущения'!$C$45*('Допущения'!$C$37*$C$10-'Допущения'!$C$53*'Допущения'!$C$55)+'Допущения'!$C$46*('Допущения'!$C$39*$C$10-'Допущения'!$C$53*'Допущения'!$C$55)+'Допущения'!$C$47*('Допущения'!$C$42*$C$10-'Допущения'!$C$53*'Допущения'!$C$55) | D13: ='Допущения'!$D$44*('Допущения'!$D$35*$D$10-'Допущения'!$D$53*'Допущения'!$D$55)+'Допущения'!$D$45*('Допущения'!$D$37*$D$10-'Допущения'!$D$53*'Допущения'!$D$55)+'Допущения'!$D$46*('Допущения'!$D$39*$D$10-'Допущения'!$D$53*'Допущения'!$D$55)+'Допущения'!$D$47*('Допущения'!$D$42*$D$10-'Допущения'!$D$53*'Допущения'!$D$55) | E13: ='Допущения'!$E$44*('Допущения'!$E$35*$E$10-'Допущения'!$E$53*'Допущения'!$E$55)+'Допущения'!$E$45*('Допущения'!$E$37*$E$10-'Допущения'!$E$53*'Допущения'!$E$55)+'Допущения'!$E$46*('Допущения'!$E$39*$E$10-'Допущения'!$E$53*'Допущения'!$E$55)+'Допущения'!$E$47*('Допущения'!$E$42*$E$10-'Допущения'!$E$53*'Допущения'!$E$55)
A14: Ожидаемые затраты на LLM на платящего | B14: $ | C14: ='Допущения'!$C$44*(('Допущения'!$C$36-0)*$C$7+0*$C$8)*'Допущения'!$C$48+'Допущения'!$C$45*(('Допущения'!$C$38-0)*$C$7+0*$C$8)*'Допущения'!$C$48+'Допущения'!$C$46*(('Допущения'!$C$40-'Допущения'!$C$41)*$C$7+'Допущения'!$C$41*$C$8)*'Допущения'!$C$48+'Допущения'!$C$47*(('Допущения'!$C$43-0)*$C$7+0*$C$8)*'Допущения'!$C$48 | D14: ='Допущения'!$D$44*(('Допущения'!$D$36-0)*$D$7+0*$D$8)*'Допущения'!$D$48+'Допущения'!$D$45*(('Допущения'!$D$38-0)*$D$7+0*$D$8)*'Допущения'!$D$48+'Допущения'!$D$46*(('Допущения'!$D$40-'Допущения'!$D$41)*$D$7+'Допущения'!$D$41*$D$8)*'Допущения'!$D$48+'Допущения'!$D$47*(('Допущения'!$D$43-0)*$D$7+0*$D$8)*'Допущения'!$D$48 | E14: ='Допущения'!$E$44*(('Допущения'!$E$36-0)*$E$7+0*$E$8)*'Допущения'!$E$48+'Допущения'!$E$45*(('Допущения'!$E$38-0)*$E$7+0*$E$8)*'Допущения'!$E$48+'Допущения'!$E$46*(('Допущения'!$E$40-'Допущения'!$E$41)*$E$7+'Допущения'!$E$41*$E$8)*'Допущения'!$E$48+'Допущения'!$E$47*(('Допущения'!$E$43-0)*$E$7+0*$E$8)*'Допущения'!$E$48 | F14: × средняя выборка лимита
A15: Валовая маржа платящего | B15: доля | C15: =IFERROR(($C$13-$C$14)/$C$13,0) | D15: =IFERROR(($D$13-$D$14)/$D$13,0) | E15: =IFERROR(($E$13-$E$14)/$E$13,0)
A16: Затраты на активного free в месяц | B16: $ | C16: ='Допущения'!$C$49*$C$7 | D16: ='Допущения'!$D$49*$D$7 | E16: ='Допущения'!$E$49*$E$7
A18: Себестоимость подписки по объёмам (базовый сценарий), лимит недели = ¼ месячного
A19: Целевая валовая маржа | D19: 0.7 | F19: Ориентир для подписок с ИИ: 60–75%
A21: Объём / модель | B21: Ходов в мес. | C21: Ходов в неделю (¼) | D21: Неделя 4: дней (мес. 28/30/31) | E21: Неделя 4: ходов в день (при 31 дне) | F21: Себест. при 100% лимита, $ | G21: Себест. ожидаемая, $ | H21: Цена при марже 70% от 100% лимита, $ | I21: Цена при марже 70% от ожидаемой, $ | J21: Себест. в ₽ (100%)
A22: 1 000 ходов — Haiku | B22: =1000 | C22: =B22/4 | D22: 7 / 9 / 10 | E22: =C22/10 | F22: =B22*$D$7 | G22: =F22*'Допущения'!$D$48 | H22: =(F22/(1-$D$19)+'Допущения'!$D$53*'Допущения'!$D$55)/$D$10 | I22: =(G22/(1-$D$19)+'Допущения'!$D$53*'Допущения'!$D$55)/$D$10 | J22: =F22*'Допущения'!$D$7
A23: Комфорт — Haiku | B23: =$D$11 | C23: =B23/4 | D23: 7 / 9 / 10 | E23: =C23/10 | F23: =B23*$D$7 | G23: =F23*'Допущения'!$D$48 | H23: =(F23/(1-$D$19)+'Допущения'!$D$53*'Допущения'!$D$55)/$D$10 | I23: =(G23/(1-$D$19)+'Допущения'!$D$53*'Допущения'!$D$55)/$D$10 | J23: =F23*'Допущения'!$D$7
A24: 10 000 ходов — Haiku | B24: =10000 | C24: =B24/4 | D24: 7 / 9 / 10 | E24: =C24/10 | F24: =B24*$D$7 | G24: =F24*'Допущения'!$D$48 | H24: =(F24/(1-$D$19)+'Допущения'!$D$53*'Допущения'!$D$55)/$D$10 | I24: =(G24/(1-$D$19)+'Допущения'!$D$53*'Допущения'!$D$55)/$D$10 | J24: =F24*'Допущения'!$D$7
A25: 1 000 ходов — мастер на Sonnet | B25: =1000 | C25: =B25/4 | D25: 7 / 9 / 10 | E25: =C25/10 | F25: =B25*$D$8 | G25: =F25*'Допущения'!$D$48 | H25: =(F25/(1-$D$19)+'Допущения'!$D$53*'Допущения'!$D$55)/$D$10 | I25: =(G25/(1-$D$19)+'Допущения'!$D$53*'Допущения'!$D$55)/$D$10 | J25: =F25*'Допущения'!$D$7
A26: Комфорт — мастер на Sonnet | B26: =$D$11 | C26: =B26/4 | D26: 7 / 9 / 10 | E26: =C26/10 | F26: =B26*$D$8 | G26: =F26*'Допущения'!$D$48 | H26: =(F26/(1-$D$19)+'Допущения'!$D$53*'Допущения'!$D$55)/$D$10 | I26: =(G26/(1-$D$19)+'Допущения'!$D$53*'Допущения'!$D$55)/$D$10 | J26: =F26*'Допущения'!$D$7
A27: 10 000 ходов — мастер на Sonnet | B27: =10000 | C27: =B27/4 | D27: 7 / 9 / 10 | E27: =C27/10 | F27: =B27*$D$8 | G27: =F27*'Допущения'!$D$48 | H27: =(F27/(1-$D$19)+'Допущения'!$D$53*'Допущения'!$D$55)/$D$10 | I27: =(G27/(1-$D$19)+'Допущения'!$D$53*'Допущения'!$D$55)/$D$10 | J27: =F27*'Допущения'!$D$7
A28: Free (30 в неделю) | B28: ='Допущения'!$D$32*4 | C28: =B28/4 | D28: 7 / 9 / 10 | E28: =C28/10 | F28: =B28*$D$7 | G28: =F28*'Допущения'!$D$48 | H28: =(F28/(1-$D$19)+'Допущения'!$D$53*'Допущения'!$D$55)/$D$10 | I28: =(G28/(1-$D$19)+'Допущения'!$D$53*'Допущения'!$D$55)/$D$10 | J28: =F28*'Допущения'!$D$7
A29: Окна лимита привязаны к дате подписки: недели 1–3 — по 7 дней, неделя 4 — с 22-го дня до продления (7–10 дней в зависимости от длины месяца). Неиспользованный остаток недели не переносится.
A31: Рекомендуемая тарифная сетка (базовый сценарий)
A32: Тариф | B32: Цена, $/мес | C32: Ходов в мес. | D32: Ходов в неделю | E32: Из них Sonnet | F32: Себест. 100% лимита, $ | G32: Себест. ожидаемая, $ | H32: Чистая выручка, $ | I32: Маржа при 100% лимита | J32: Маржа ожидаемая
A33: Free | B33: 0 | C33: ='Допущения'!$D$32*4 | D33: ='Допущения'!$D$32 | E33: 0 | F33: =C33*$D$7 | G33: ='Допущения'!$D$49*$D$7 | H33: 0 | I33: — | J33: —
A34: Teen 13–17 | B34: ='Допущения'!$D$35 | C34: ='Допущения'!$D$36 | D34: =C34/4 | E34: 0 | F34: =(('Допущения'!$D$36-0)*$D$7+0*$D$8) | G34: =(('Допущения'!$D$36-0)*$D$7+0*$D$8)*'Допущения'!$D$48 | H34: =('Допущения'!$D$35*$D$10-'Допущения'!$D$53*'Допущения'!$D$55) | I34: =IFERROR((H34-F34)/H34,0) | J34: =IFERROR((H34-G34)/H34,0)
A35: Standard | B35: ='Допущения'!$D$37 | C35: ='Допущения'!$D$38 | D35: =C35/4 | E35: 0 | F35: =(('Допущения'!$D$38-0)*$D$7+0*$D$8) | G35: =(('Допущения'!$D$38-0)*$D$7+0*$D$8)*'Допущения'!$D$48 | H35: =('Допущения'!$D$37*$D$10-'Допущения'!$D$53*'Допущения'!$D$55) | I35: =IFERROR((H35-F35)/H35,0) | J35: =IFERROR((H35-G35)/H35,0)
A36: Premium | B36: ='Допущения'!$D$39 | C36: ='Допущения'!$D$40 | D36: =C36/4 | E36: ='Допущения'!$D$41 | F36: =(('Допущения'!$D$40-'Допущения'!$D$41)*$D$7+'Допущения'!$D$41*$D$8) | G36: =(('Допущения'!$D$40-'Допущения'!$D$41)*$D$7+'Допущения'!$D$41*$D$8)*'Допущения'!$D$48 | H36: =('Допущения'!$D$39*$D$10-'Допущения'!$D$53*'Допущения'!$D$55) | I36: =IFERROR((H36-F36)/H36,0) | J36: =IFERROR((H36-G36)/H36,0)
A37: Legend 10 000 | B37: ='Допущения'!$D$42 | C37: ='Допущения'!$D$43 | D37: =C37/4 | E37: 0 | F37: =(('Допущения'!$D$43-0)*$D$7+0*$D$8) | G37: =(('Допущения'!$D$43-0)*$D$7+0*$D$8)*'Допущения'!$D$48 | H37: =('Допущения'!$D$42*$D$10-'Допущения'!$D$53*'Допущения'!$D$55) | I37: =IFERROR((H37-F37)/H37,0) | J37: =IFERROR((H37-G37)/H37,0)
A38: Отрицательная маржа при 100% лимита — риск «китов». Защита: недельные окна, мягкое замедление после 80% лимита, честное «fair use» в условиях.

Sheet Старт
A1: Стартовые разовые затраты (регулярные — в «Модель_*»)
A2: Месяц — номер месяца модели (1 = ноябрь 2026). Суммы — оценки по открытым источникам на 17.10.2026; по юр. услугам запросить 2–3 КП.
A4: Статья | B4: Этап | C4: Месяц | D4: Сумма, $ | E4: Сумма, ₽ | F4: Обязательность | G4: Источник / комментарий
A5: Домен .com/.app + почта на год | B5: 0. Прототип | C5: =1 | D5: 40 | E5: =D5*'Допущения'!$D$7 | F5: обяз. | G5: Cloudflare Registrar / Namecheap
A6: Б/у Android-телефон для тестов | B6: 0. Прототип | C6: =1 | D6: 150 | E6: =D6*'Допущения'!$D$7 | F6: желат. | G6: Сейчас — эмулятор; нужен реальный девайс
A7: Госпошлина ООО, юр. адрес на год, переводы и нотариус | B7: 1. До MVP | C7: ='Допущения'!$D$10 | D7: 250 | E7: =D7*'Допущения'!$D$7 | F7: обяз. | G7: Дом юстиции: 100–200 GEL; юр. адрес ~$100–150/год
A8: Юрист: устав ООО с вестингом + соглашение участников | B8: 1. До MVP | C8: ='Допущения'!$D$10 | D8: 1000 | E8: =D8*'Допущения'!$D$7 | F8: обяз. | G8: Под ключ $500–1000 + SHA; запросить КП
A9: Регистрация ИП ×2 + статус малого бизнеса (1%) | B9: 1. До MVP | C9: ='Допущения'!$D$10 | D9: 200 | E9: =D9*'Допущения'!$D$7 | F9: желат. | G9: Для выплат основателям по договорам услуг
A10: Разрешения на работу (Special Labour Permit) ×2 с сопровождением | B10: 1. До MVP | C10: ='Допущения'!$D$10 | D10: 600 | E10: =D10*'Допущения'!$D$7 | F10: обяз. | G10: С 01.03.2026 нужны директору ООО и ИП-иностранцу; пошлину уточнить
A11: Статус Virtual Zone (заявка через провайдера) | B11: 1. До MVP | C11: ='Допущения'!$D$10+1 | D11: 670 | E11: =D11*'Допущения'!$D$7 | F11: обяз. | G11: 1 500 GEL + НДС (ExpatHub) ≈ $670
A12: Товарный знак США (USPTO), 2 класса (9, 41) | B12: 1. До MVP | C12: ='Допущения'!$D$10+1 | D12: 700 | E12: =D12*'Допущения'!$D$7 | F12: желат. | G12: $350 за класс (2026)
A13: Патентный поверенный (поиск, подача) | B13: 1. До MVP | C13: ='Допущения'!$D$10+1 | D13: 500 | E13: =D13*'Допущения'!$D$7 | F13: желат. | G13: Оценка
A14: ToS, Privacy Policy, AI-дисклеймеры, политика безопасности — проверка юристом | B14: 1. До MVP | C14: ='Допущения'!$D$9-1 | D14: 1200 | E14: =D14*'Допущения'!$D$7 | F14: обяз. | G14: COPPA, GDPR, CCPA, SB 243, EU AI Act ст. 50
A15: Материалы магазинов: иконка, скриншоты, трейлер | B15: 1. До MVP | C15: ='Допущения'!$D$9-1 | D15: 300 | E15: =D15*'Допущения'!$D$7 | F15: обяз. | G15: Делаю сам + генерация; бюджет на стоки/озвучку
A16: Набор тестов безопасности (кризисные сценарии), red-teaming | B16: 1. До MVP | C16: ='Допущения'!$D$9-1 | D16: 300 | E16: =D16*'Допущения'!$D$7 | F16: обяз. | G16: Внешний тестировщик-модератор, разово
A17: Товарный знак ЕС (EUIPO), 2 класса | B17: 2. После выхода | C17: ='Допущения'!$D$9+4 | D17: 1050 | E17: =D17*'Допущения'!$D$7 | F17: желат. | G17: €850 + €50 ≈ $1 050
A18: Итого разовые | D18: =SUM(D5:D17) | E18: =SUM(E5:E17)
A19: в т. ч. обязательные | D19: =SUMIF(F5:F17,"обяз.",D5:D17) | E19: =D19*'Допущения'!$D$7
A21: Бюджет до выхода MVP включительно (из модели, все затраты)
A22: Пессимистичный: расходы мес. 1 … выход | D22: ='Модель_П'!$B$99 | E22: =D22*'Допущения'!$D$7
A23: Базовый: расходы мес. 1 … выход | D23: ='Модель_Б'!$B$99 | E23: =D23*'Допущения'!$D$7
A24: Оптимистичный: расходы мес. 1 … выход | D24: ='Модель_О'!$B$99 | E24: =D24*'Допущения'!$D$7
A25: Резерв на непредвиденное | C25: 0.15
A26: Базовый: стартовый бюджет с резервом | D26: =D23*(1+C25) | E26: =D26*'Допущения'!$D$7

Sheet Модель_Б
A1: Финмодель на 36 месяцев — сценарий: Базовый
A2: Все значения считаются формулами из листов «Допущения», «Себестоимость», «Старт».
B5: Итого / знач.
A6: Месяц № | C6: 1 | D6: 2 | E6: 3 | F6: 4 | G6: 5 | H6: 6 | I6: 7 | J6: 8 | K6: 9 | L6: 10 | M6: 11 | N6: 12 | O6: 13 | P6: 14 | Q6: 15 | R6: 16 | S6: 17 | T6: 18 | U6: 19 | V6: 20 | W6: 21 | X6: 22 | Y6: 23 | Z6: 24 | AA6: 25 | AB6: 26 | AC6: 27 | AD6: 28 | AE6: 29 | AF6: 30 | AG6: 31 | AH6: 32 | AI6: 33 | AJ6: 34 | AK6: 35 | AL6: 36
A7: Месяц | C7: ноя 2026 | D7: дек 2026 | E7: янв 2027 | F7: фев 2027 | G7: мар 2027 | H7: апр 2027 | I7: май 2027 | J7: июн 2027 | K7: июл 2027 | L7: авг 2027 | M7: сен 2027 | N7: окт 2027 | O7: ноя 2027 | P7: дек 2027 | Q7: янв 2028 | R7: фев 2028 | S7: мар 2028 | T7: апр 2028 | U7: май 2028 | V7: июн 2028 | W7: июл 2028 | X7: авг 2028 | Y7: сен 2028 | Z7: окт 2028 | AA7: ноя 2028 | AB7: дек 2028 | AC7: янв 2029 | AD7: фев 2029 | AE7: мар 2029 | AF7: апр 2029 | AG7: май 2029 | AH7: июн 2029 | AI7: июл 2029 | AJ7: авг 2029 | AK7: сен 2029 | AL7: окт 2029
A8: Год проекта | C8: 1 | D8: 1 | E8: 1 | F8: 1 | G8: 1 | H8: 1 | I8: 1 | J8: 1 | K8: 1 | L8: 1 | M8: 1 | N8: 1 | O8: 2 | P8: 2 | Q8: 2 | R8: 2 | S8: 2 | T8: 2 | U8: 2 | V8: 2 | W8: 2 | X8: 2 | Y8: 2 | Z8: 2 | AA8: 3 | AB8: 3 | AC8: 3 | AD8: 3 | AE8: 3 | AF8: 3 | AG8: 3 | AH8: 3 | AI8: 3 | AJ8: 3 | AK8: 3 | AL8: 3
A9: Рынок (1 = MVP вышел) | C9: =IF(C6>='Допущения'!$D$9,1,0) | D9: =IF(D6>='Допущения'!$D$9,1,0) | E9: =IF(E6>='Допущения'!$D$9,1,0) | F9: =IF(F6>='Допущения'!$D$9,1,0) | G9: =IF(G6>='Допущения'!$D$9,1,0) | H9: =IF(H6>='Допущения'!$D$9,1,0) | I9: =IF(I6>='Допущения'!$D$9,1,0) | J9: =IF(J6>='Допущения'!$D$9,1,0) | ... AL9: =IF(AL6>='Допущения'!$D$9,1,0)
A10: ВОРОНКА
A11: Маркетинг, $ | B11: =SUM(C11:AL11) | C11: =IF(C9=1,MAX('Допущения'!$D$83,'Допущения'!$D$84*0)+IF(C6='Допущения'!$D$9,'Допущения'!$D$82,0),'Допущения'!$D$81) | D11: =IF(D9=1,MAX('Допущения'!$D$83,'Допущения'!$D$84*C28)+IF(D6='Допущения'!$D$9,'Допущения'!$D$82,0),'Допущения'!$D$81) | E11: =IF(E9=1,MAX('Допущения'!$D$83,'Допущения'!$D$84*D28)+IF(E6='Допущения'!$D$9,'Допущения'!$D$82,0),'Допущения'!$D$81) | F11: =IF(F9=1,MAX('Допущения'!$D$83,'Допущения'!$D$84*E28)+IF(F6='Допущения'!$D$9,'Допущения'!$D$82,0),'Допущения'!$D$81) | G11: =IF(G9=1,MAX('Допущения'!$D$83,'Допущения'!$D$84*F28)+IF(G6='Допущения'!$D$9,'Допущения'!$D$82,0),'Допущения'!$D$81) | H11: =IF(H9=1,MAX('Допущения'!$D$83,'Допущения'!$D$84*G28)+IF(H6='Допущения'!$D$9,'Допущения'!$D$82,0),'Допущения'!$D$81) | I11: =IF(I9=1,MAX('Допущения'!$D$83,'Допущения'!$D$84*H28)+IF(I6='Допущения'!$D$9,'Допущения'!$D$82,0),'Допущения'!$D$81) | J11: =IF(J9=1,MAX('Допущения'!$D$83,'Допущения'!$D$84*I28)+IF(J6='Допущения'!$D$9,'Допущения'!$D$82,0),'Допущения'!$D$81) | K11: =IF(K9=1,MAX('Допущения'!$D$83,'Допущения'!$D$84*J28)+IF(K6='Допущения'!$D$9,'Допущения'!$D$82,0),'Допущения'!$D$81) | ... AL11: =IF(AL9=1,MAX('Допущения'!$D$83,'Допущения'!$D$84*AK28)+IF(AL6='Допущения'!$D$9,'Допущения'!$D$82,0),'Допущения'!$D$81)
A12: Платные установки | B12: =SUM(C12:AL12) | C12: =IF(C9=1,C11/'Допущения'!$D$60,0) | D12: =IF(D9=1,D11/'Допущения'!$D$60,0) | E12: =IF(E9=1,E11/'Допущения'!$D$60,0) | F12: =IF(F9=1,F11/'Допущения'!$D$60,0) | G12: =IF(G9=1,G11/'Допущения'!$D$60,0) | H12: =IF(H9=1,H11/'Допущения'!$D$60,0) | I12: =IF(I9=1,I11/'Допущения'!$D$60,0) | J12: =IF(J9=1,J11/'Допущения'!$D$60,0) | ... AL12: =IF(AL9=1,AL11/'Допущения'!$D$60,0)
A13: Органические установки | B13: =SUM(C13:AL13) | C13: =IF(C9=1,MIN('Допущения'!$D$63,'Допущения'!$D$61*(1+'Допущения'!$D$62)^(C6-'Допущения'!$D$9)),0) | D13: =IF(D9=1,MIN('Допущения'!$D$63,'Допущения'!$D$61*(1+'Допущения'!$D$62)^(D6-'Допущения'!$D$9)),0) | E13: =IF(E9=1,MIN('Допущения'!$D$63,'Допущения'!$D$61*(1+'Допущения'!$D$62)^(E6-'Допущения'!$D$9)),0) | F13: =IF(F9=1,MIN('Допущения'!$D$63,'Допущения'!$D$61*(1+'Допущения'!$D$62)^(F6-'Допущения'!$D$9)),0) | G13: =IF(G9=1,MIN('Допущения'!$D$63,'Допущения'!$D$61*(1+'Допущения'!$D$62)^(G6-'Допущения'!$D$9)),0) | H13: =IF(H9=1,MIN('Допущения'!$D$63,'Допущения'!$D$61*(1+'Допущения'!$D$62)^(H6-'Допущения'!$D$9)),0) | I13: =IF(I9=1,MIN('Допущения'!$D$63,'Допущения'!$D$61*(1+'Допущения'!$D$62)^(I6-'Допущения'!$D$9)),0) | J13: =IF(J9=1,MIN('Допущения'!$D$63,'Допущения'!$D$61*(1+'Допущения'!$D$62)^(J6-'Допущения'!$D$9)),0) | ... AL13: =IF(AL9=1,MIN('Допущения'!$D$63,'Допущения'!$D$61*(1+'Допущения'!$D$62)^(AL6-'Допущения'!$D$9)),0)
A14: Вирусные установки | B14: =SUM(C14:AL14) | C14: =(C12+C13)*'Допущения'!$D$64 | D14: =(D12+D13)*'Допущения'!$D$64 | E14: =(E12+E13)*'Допущения'!$D$64 | F14: =(F12+F13)*'Допущения'!$D$64 | G14: =(G12+G13)*'Допущения'!$D$64 | H14: =(H12+H13)*'Допущения'!$D$64 | I14: =(I12+I13)*'Допущения'!$D$64 | J14: =(J12+J13)*'Допущения'!$D$64 | ... AL14: =(AL12+AL13)*'Допущения'!$D$64
A15: Всего установок | B15: =SUM(C15:AL15) | C15: =C12+C13+C14 | D15: =D12+D13+D14 | E15: =E12+E13+E14 | F15: =F12+F13+F14 | G15: =G12+G13+G14 | H15: =H12+H13+H14 | I15: =I12+I13+I14 | J15: =J12+J13+J14 | ... AL15: =AL12+AL13+AL14
A16: Новые активированные | B16: =SUM(C16:AL16) | C16: =C15*'Допущения'!$D$65+IF(C6='Допущения'!$D$9,0*'Допущения'!$D$78,0) | D16: =D15*'Допущения'!$D$65+IF(D6='Допущения'!$D$9,C17*'Допущения'!$D$78,0) | E16: =E15*'Допущения'!$D$65+IF(E6='Допущения'!$D$9,D17*'Допущения'!$D$78,0) | F16: =F15*'Допущения'!$D$65+IF(F6='Допущения'!$D$9,E17*'Допущения'!$D$78,0) | G16: =G15*'Допущения'!$D$65+IF(G6='Допущения'!$D$9,F17*'Допущения'!$D$78,0) | H16: =H15*'Допущения'!$D$65+IF(H6='Допущения'!$D$9,G17*'Допущения'!$D$78,0) | I16: =I15*'Допущения'!$D$65+IF(I6='Допущения'!$D$9,H17*'Допущения'!$D$78,0) | J16: =J15*'Допущения'!$D$65+IF(J6='Допущения'!$D$9,I17*'Допущения'!$D$78,0) | K16: =K15*'Допущения'!$D$65+IF(K6='Допущения'!$D$9,J17*'Допущения'!$D$78,0) | ... AL16: =AL15*'Допущения'!$D$65+IF(AL6='Допущения'!$D$9,AK17*'Допущения'!$D$78,0)
A17: Игроки прототипа (до выхода) | C17: =IF(C9=1,0,'Допущения'!$D$72*(1+'Допущения'!$D$73)^(C6-1)) | D17: =IF(D9=1,0,'Допущения'!$D$72*(1+'Допущения'!$D$73)^(D6-1)) | E17: =IF(E9=1,0,'Допущения'!$D$72*(1+'Допущения'!$D$73)^(E6-1)) | F17: =IF(F9=1,0,'Допущения'!$D$72*(1+'Допущения'!$D$73)^(F6-1)) | G17: =IF(G9=1,0,'Допущения'!$D$72*(1+'Допущения'!$D$73)^(G6-1)) | H17: =IF(H9=1,0,'Допущения'!$D$72*(1+'Допущения'!$D$73)^(H6-1)) | I17: =IF(I9=1,0,'Допущения'!$D$72*(1+'Допущения'!$D$73)^(I6-1)) | J17: =IF(J9=1,0,'Допущения'!$D$72*(1+'Допущения'!$D$73)^(J6-1)) | ... AL17: =IF(AL9=1,0,'Допущения'!$D$72*(1+'Допущения'!$D$73)^(AL6-1))
A18: Активные free (на конец мес.) | C18: =IF(C9=1,0*(1-'Допущения'!$D$68)*'Допущения'!$D$66+C16*(1-'Допущения'!$D$67),0) | D18: =IF(D9=1,C18*(1-'Допущения'!$D$68)*'Допущения'!$D$66+D16*(1-'Допущения'!$D$67),0) | E18: =IF(E9=1,D18*(1-'Допущения'!$D$68)*'Допущения'!$D$66+E16*(1-'Допущения'!$D$67),0) | F18: =IF(F9=1,E18*(1-'Допущения'!$D$68)*'Допущения'!$D$66+F16*(1-'Допущения'!$D$67),0) | G18: =IF(G9=1,F18*(1-'Допущения'!$D$68)*'Допущения'!$D$66+G16*(1-'Допущения'!$D$67),0) | H18: =IF(H9=1,G18*(1-'Допущения'!$D$68)*'Допущения'!$D$66+H16*(1-'Допущения'!$D$67),0) | I18: =IF(I9=1,H18*(1-'Допущения'!$D$68)*'Допущения'!$D$66+I16*(1-'Допущения'!$D$67),0) | J18: =IF(J9=1,I18*(1-'Допущения'!$D$68)*'Допущения'!$D$66+J16*(1-'Допущения'!$D$67),0) | K18: =IF(K9=1,J18*(1-'Допущения'!$D$68)*'Допущения'!$D$66+K16*(1-'Допущения'!$D$67),0) | ... AL18: =IF(AL9=1,AK18*(1-'Допущения'!$D$68)*'Допущения'!$D$66+AL16*(1-'Допущения'!$D$67),0)
A19: Новые платящие | B19: =SUM(C19:AL19) | C19: =IF(C9=1,C16*'Допущения'!$D$67+0*'Допущения'!$D$68,0) | D19: =IF(D9=1,D16*'Допущения'!$D$67+C18*'Допущения'!$D$68,0) | E19: =IF(E9=1,E16*'Допущения'!$D$67+D18*'Допущения'!$D$68,0) | F19: =IF(F9=1,F16*'Допущения'!$D$67+E18*'Допущения'!$D$68,0) | G19: =IF(G9=1,G16*'Допущения'!$D$67+F18*'Допущения'!$D$68,0) | H19: =IF(H9=1,H16*'Допущения'!$D$67+G18*'Допущения'!$D$68,0) | I19: =IF(I9=1,I16*'Допущения'!$D$67+H18*'Допущения'!$D$68,0) | J19: =IF(J9=1,J16*'Допущения'!$D$67+I18*'Допущения'!$D$68,0) | K19: =IF(K9=1,K16*'Допущения'!$D$67+J18*'Допущения'!$D$68,0) | ... AL19: =IF(AL9=1,AL16*'Допущения'!$D$67+AK18*'Допущения'!$D$68,0)
A20: Ушедшие платящие | B20: =SUM(C20:AL20) | C20: =0*'Допущения'!$D$69 | D20: =C21*'Допущения'!$D$69 | E20: =D21*'Допущения'!$D$69 | F20: =E21*'Допущения'!$D$69 | G20: =F21*'Допущения'!$D$69 | H20: =G21*'Допущения'!$D$69 | I20: =H21*'Допущения'!$D$69 | J20: =I21*'Допущения'!$D$69 | K20: =J21*'Допущения'!$D$69 | ... AL20: =AK21*'Допущения'!$D$69
A21: Платящие (на конец мес.) | C21: =0+C19-C20 | D21: =C21+D19-D20 | E21: =D21+E19-E20 | F21: =E21+F19-F20 | G21: =F21+G19-G20 | H21: =G21+H19-H20 | I21: =H21+I19-I20 | J21: =I21+J19-J20 | K21: =J21+K19-K20 | ... AL21: =AK21+AL19-AL20
A22: Активные пользователи всего | C22: =C17+C18+C21 | D22: =D17+D18+D21 | E22: =E17+E18+E21 | F22: =F17+F18+F21 | G22: =G17+G18+G21 | H22: =H17+H18+H21 | I22: =I17+I18+I21 | J22: =J17+J18+J21 | ... AL22: =AL17+AL18+AL21
A23: ВЫРУЧКА, $
A24: Оплаты подписок (брутто) | B24: =SUM(C24:AL24) | C24: =C21*'Себестоимость'!$D$12 | D24: =D21*'Себестоимость'!$D$12 | E24: =E21*'Себестоимость'!$D$12 | F24: =F21*'Себестоимость'!$D$12 | G24: =G21*'Себестоимость'!$D$12 | H24: =H21*'Себестоимость'!$D$12 | I24: =I21*'Себестоимость'!$D$12 | J24: =J21*'Себестоимость'!$D$12 | ... AL24: =AL21*'Себестоимость'!$D$12
A25: Комиссии магазинов/Paddle и НДС | B25: =SUM(C25:AL25) | C25: =C24-C26 | D25: =D24-D26 | E25: =E24-E26 | F25: =F24-F26 | G25: =G24-G26 | H25: =H24-H26 | I25: =I24-I26 | J25: =J24-J26 | ... AL25: =AL24-AL26
A26: Чистая выручка подписок | B26: =SUM(C26:AL26) | C26: =C21*'Себестоимость'!$D$13 | D26: =D21*'Себестоимость'!$D$13 | E26: =E21*'Себестоимость'!$D$13 | F26: =F21*'Себестоимость'!$D$13 | G26: =G21*'Себестоимость'!$D$13 | H26: =H21*'Себестоимость'!$D$13 | I26: =I21*'Себестоимость'!$D$13 | J26: =J21*'Себестоимость'!$D$13 | ... AL26: =AL21*'Себестоимость'!$D$13
A27: Донаты (чистые) | B27: =SUM(C27:AL27) | C27: =C17*'Допущения'!$D$75*'Допущения'!$D$76*(1-'Допущения'!$D$77) | D27: =D17*'Допущения'!$D$75*'Допущения'!$D$76*(1-'Допущения'!$D$77) | E27: =E17*'Допущения'!$D$75*'Допущения'!$D$76*(1-'Допущения'!$D$77) | F27: =F17*'Допущения'!$D$75*'Допущения'!$D$76*(1-'Допущения'!$D$77) | G27: =G17*'Допущения'!$D$75*'Допущения'!$D$76*(1-'Допущения'!$D$77) | H27: =H17*'Допущения'!$D$75*'Допущения'!$D$76*(1-'Допущения'!$D$77) | I27: =I17*'Допущения'!$D$75*'Допущения'!$D$76*(1-'Допущения'!$D$77) | J27: =J17*'Допущения'!$D$75*'Допущения'!$D$76*(1-'Допущения'!$D$77) | ... AL27: =AL17*'Допущения'!$D$75*'Допущения'!$D$76*(1-'Допущения'!$D$77)
A28: Итого чистая выручка | B28: =SUM(C28:AL28) | C28: =C26+C27 | D28: =D26+D27 | E28: =E26+E27 | F28: =F26+F27 | G28: =G26+G27 | H28: =H26+H27 | I28: =I26+I27 | J28: =J26+J27 | ... AL28: =AL26+AL27
A29: ПЕРЕМЕННЫЕ ЗАТРАТЫ, $
A30: LLM: платящие | B30: =SUM(C30:AL30) | C30: =C21*'Себестоимость'!$D$14 | D30: =D21*'Себестоимость'!$D$14 | E30: =E21*'Себестоимость'!$D$14 | F30: =F21*'Себестоимость'!$D$14 | G30: =G21*'Себестоимость'!$D$14 | H30: =H21*'Себестоимость'!$D$14 | I30: =I21*'Себестоимость'!$D$14 | J30: =J21*'Себестоимость'!$D$14 | ... AL30: =AL21*'Себестоимость'!$D$14
A31: LLM: free и прототип | B31: =SUM(C31:AL31) | C31: =C18*'Себестоимость'!$D$16+C17*'Допущения'!$D$74*'Себестоимость'!$D$7 | D31: =D18*'Себестоимость'!$D$16+D17*'Допущения'!$D$74*'Себестоимость'!$D$7 | E31: =E18*'Себестоимость'!$D$16+E17*'Допущения'!$D$74*'Себестоимость'!$D$7 | F31: =F18*'Себестоимость'!$D$16+F17*'Допущения'!$D$74*'Себестоимость'!$D$7 | G31: =G18*'Себестоимость'!$D$16+G17*'Допущения'!$D$74*'Себестоимость'!$D$7 | H31: =H18*'Себестоимость'!$D$16+H17*'Допущения'!$D$74*'Себестоимость'!$D$7 | I31: =I18*'Себестоимость'!$D$16+I17*'Допущения'!$D$74*'Себестоимость'!$D$7 | J31: =J18*'Себестоимость'!$D$16+J17*'Допущения'!$D$74*'Себестоимость'!$D$7 | ... AL31: =AL18*'Себестоимость'!$D$16+AL17*'Допущения'!$D$74*'Себестоимость'!$D$7
A32: Проверка возраста | B32: =SUM(C32:AL32) | C32: =C19*'Допущения'!$D$44*'Допущения'!$D$93 | D32: =D19*'Допущения'!$D$44*'Допущения'!$D$93 | E32: =E19*'Допущения'!$D$44*'Допущения'!$D$93 | F32: =F19*'Допущения'!$D$44*'Допущения'!$D$93 | G32: =G19*'Допущения'!$D$44*'Допущения'!$D$93 | H32: =H19*'Допущения'!$D$44*'Допущения'!$D$93 | I32: =I19*'Допущения'!$D$44*'Допущения'!$D$93 | J32: =J19*'Допущения'!$D$44*'Допущения'!$D$93 | ... AL32: =AL19*'Допущения'!$D$44*'Допущения'!$D$93
A33: Инфраструктура (на пользователя) | B33: =SUM(C33:AL33) | C33: =C22*'Допущения'!$D$86 | D33: =D22*'Допущения'!$D$86 | E33: =E22*'Допущения'!$D$86 | F33: =F22*'Допущения'!$D$86 | G33: =G22*'Допущения'!$D$86 | H33: =H22*'Допущения'!$D$86 | I33: =I22*'Допущения'!$D$86 | J33: =J22*'Допущения'!$D$86 | ... AL33: =AL22*'Допущения'!$D$86
A34: Итого переменные | B34: =SUM(C34:AL34) | C34: =SUM(C30:C33) | D34: =SUM(D30:D33) | E34: =SUM(E30:E33) | F34: =SUM(F30:F33) | G34: =SUM(G30:G33) | H34: =SUM(H30:H33) | I34: =SUM(I30:I33) | J34: =SUM(J30:J33) | ... AL34: =SUM(AL30:AL33)
A35: Валовая прибыль | B35: =SUM(C35:AL35) | C35: =C28-C34 | D35: =D28-D34 | E35: =E28-E34 | F35: =F28-F34 | G35: =G28-G34 | H35: =H28-H34 | I35: =I28-I34 | J35: =J28-J34 | ... AL35: =AL28-AL34
A36: Валовая маржа | B36: =IFERROR(B35/B28,0) | C36: =IFERROR(C35/C28,0) | D36: =IFERROR(D35/D28,0) | E36: =IFERROR(E35/E28,0) | F36: =IFERROR(F35/F28,0) | G36: =IFERROR(G35/G28,0) | H36: =IFERROR(H35/H28,0) | I36: =IFERROR(I35/I28,0) | ... AL36: =IFERROR(AL35/AL28,0)
A37: ПОСТОЯННЫЕ ЗАТРАТЫ И МАРКЕТИНГ, $
A38: Инфраструктура (база) | B38: =SUM(C38:AL38) | C38: ='Допущения'!$D$85 | D38: ='Допущения'!$D$85 | E38: ='Допущения'!$D$85 | F38: ='Допущения'!$D$85 | G38: ='Допущения'!$D$85 | H38: ='Допущения'!$D$85 | I38: ='Допущения'!$D$85 | J38: ='Допущения'!$D$85 | ... AL38: ='Допущения'!$D$85
A39: SaaS-инструменты | B39: =SUM(C39:AL39) | C39: ='Допущения'!$D$87 | D39: ='Допущения'!$D$87 | E39: ='Допущения'!$D$87 | F39: ='Допущения'!$D$87 | G39: ='Допущения'!$D$87 | H39: ='Допущения'!$D$87 | I39: ='Допущения'!$D$87 | J39: ='Допущения'!$D$87 | ... AL39: ='Допущения'!$D$87
A40: Бухгалтерия | B40: =SUM(C40:AL40) | C40: =IF(C6>='Допущения'!$D$10,'Допущения'!$D$88,0) | D40: =IF(D6>='Допущения'!$D$10,'Допущения'!$D$88,0) | E40: =IF(E6>='Допущения'!$D$10,'Допущения'!$D$88,0) | F40: =IF(F6>='Допущения'!$D$10,'Допущения'!$D$88,0) | G40: =IF(G6>='Допущения'!$D$10,'Допущения'!$D$88,0) | H40: =IF(H6>='Допущения'!$D$10,'Допущения'!$D$88,0) | I40: =IF(I6>='Допущения'!$D$10,'Допущения'!$D$88,0) | J40: =IF(J6>='Допущения'!$D$10,'Допущения'!$D$88,0) | ... AL40: =IF(AL6>='Допущения'!$D$10,'Допущения'!$D$88,0)
A41: Юр. сопровождение | B41: =SUM(C41:AL41) | C41: =IF(C9=1,'Допущения'!$D$89,0) | D41: =IF(D9=1,'Допущения'!$D$89,0) | E41: =IF(E9=1,'Допущения'!$D$89,0) | F41: =IF(F9=1,'Допущения'!$D$89,0) | G41: =IF(G9=1,'Допущения'!$D$89,0) | H41: =IF(H9=1,'Допущения'!$D$89,0) | I41: =IF(I9=1,'Допущения'!$D$89,0) | J41: =IF(J9=1,'Допущения'!$D$89,0) | ... AL41: =IF(AL9=1,'Допущения'!$D$89,0)
A42: Магазины приложений | B42: =SUM(C42:AL42) | C42: =IF(C6='Допущения'!$D$9-1,'Допущения'!$D$90+'Допущения'!$D$91,0)+IF(AND(C6>'Допущения'!$D$9-1,MOD(C6-('Допущения'!$D$9-1),12)=0),'Допущения'!$D$90,0) | D42: =IF(D6='Допущения'!$D$9-1,'Допущения'!$D$90+'Допущения'!$D$91,0)+IF(AND(D6>'Допущения'!$D$9-1,MOD(D6-('Допущения'!$D$9-1),12)=0),'Допущения'!$D$90,0) | E42: =IF(E6='Допущения'!$D$9-1,'Допущения'!$D$90+'Допущения'!$D$91,0)+IF(AND(E6>'Допущения'!$D$9-1,MOD(E6-('Допущения'!$D$9-1),12)=0),'Допущения'!$D$90,0) | F42: =IF(F6='Допущения'!$D$9-1,'Допущения'!$D$90+'Допущения'!$D$91,0)+IF(AND(F6>'Допущения'!$D$9-1,MOD(F6-('Допущения'!$D$9-1),12)=0),'Допущения'!$D$90,0) | G42: =IF(G6='Допущения'!$D$9-1,'Допущения'!$D$90+'Допущения'!$D$91,0)+IF(AND(G6>'Допущения'!$D$9-1,MOD(G6-('Допущения'!$D$9-1),12)=0),'Допущения'!$D$90,0) | H42: =IF(H6='Допущения'!$D$9-1,'Допущения'!$D$90+'Допущения'!$D$91,0)+IF(AND(H6>'Допущения'!$D$9-1,MOD(H6-('Допущения'!$D$9-1),12)=0),'Допущения'!$D$90,0) | I42: =IF(I6='Допущения'!$D$9-1,'Допущения'!$D$90+'Допущения'!$D$91,0)+IF(AND(I6>'Допущения'!$D$9-1,MOD(I6-('Допущения'!$D$9-1),12)=0),'Допущения'!$D$90,0) | J42: =IF(J6='Допущения'!$D$9-1,'Допущения'!$D$90+'Допущения'!$D$91,0)+IF(AND(J6>'Допущения'!$D$9-1,MOD(J6-('Допущения'!$D$9-1),12)=0),'Допущения'!$D$90,0) | ... AL42: =IF(AL6='Допущения'!$D$9-1,'Допущения'!$D$90+'Допущения'!$D$91,0)+IF(AND(AL6>'Допущения'!$D$9-1,MOD(AL6-('Допущения'!$D$9-1),12)=0),'Допущения'!$D$90,0)
...

Sheet Модель_П
A1: Финмодель на 36 месяцев — сценарий: Пессимистичный
A2: Все значения считаются формулами из листов «Допущения», «Себестоимость», «Старт».
B5: Итого / знач.
A6: Месяц № | C6: 1 | D6: 2 | E6: 3 | F6: 4 | G6: 5 | H6: 6 | I6: 7 | J6: 8 | K6: 9 | L6: 10 | M6: 11 | N6: 12 | O6: 13 | P6: 14 | Q6: 15 | R6: 16 | S6: 17 | T6: 18 | U6: 19 | V6: 20 | W6: 21 | X6: 22 | Y6: 23 | Z6: 24 | AA6: 25 | AB6: 26 | AC6: 27 | AD6: 28 | AE6: 29 | AF6: 30 | AG6: 31 | AH6: 32 | AI6: 33 | AJ6: 34 | AK6: 35 | AL6: 36
A7: Месяц | C7: ноя 2026 | D7: дек 2026 | E7: янв 2027 | F7: фев 2027 | G7: мар 2027 | H7: апр 2027 | I7: май 2027 | J7: июн 2027 | K7: июл 2027 | L7: авг 2027 | M7: сен 2027 | N7: окт 2027 | O7: ноя 2027 | P7: дек 2027 | Q7: янв 2028 | R7: фев 2028 | S7: мар 2028 | T7: апр 2028 | U7: май 2028 | V7: июн 2028 | W7: июл 2028 | X7: авг 2028 | Y7: сен 2028 | Z7: окт 2028 | AA7: ноя 2028 | AB7: дек 2028 | AC7: янв 2029 | AD7: фев 2029 | AE7: мар 2029 | AF7: апр 2029 | AG7: май 2029 | AH7: июн 2029 | AI7: июл 2029 | AJ7: авг 2029 | AK7: сен 2029 | AL7: окт 2029
A8: Год проекта | C8: 1 | D8: 1 | E8: 1 | F8: 1 | G8: 1 | H8: 1 | I8: 1 | J8: 1 | K8: 1 | L8: 1 | M8: 1 | N8: 1 | O8: 2 | P8: 2 | Q8: 2 | R8: 2 | S8: 2 | T8: 2 | U8: 2 | V8: 2 | W8: 2 | X8: 2 | Y8: 2 | Z8: 2 | AA8: 3 | AB8: 3 | AC8: 3 | AD8: 3 | AE8: 3 | AF8: 3 | AG8: 3 | AH8: 3 | AI8: 3 | AJ8: 3 | AK8: 3 | AL8: 3
A9: Рынок (1 = MVP вышел) | C9: =IF(C6>='Допущения'!$C$9,1,0) | D9: =IF(D6>='Допущения'!$C$9,1,0) | E9: =IF(E6>='Допущения'!$C$9,1,0) | F9: =IF(F6>='Допущения'!$C$9,1,0) | G9: =IF(G6>='Допущения'!$C$9,1,0) | H9: =IF(H6>='Допущения'!$C$9,1,0) | I9: =IF(I6>='Допущения'!$C$9,1,0) | J9: =IF(J6>='Допущения'!$C$9,1,0) | ... AL9: =IF(AL6>='Допущения'!$C$9,1,0)
A10: ВОРОНКА
A11: Маркетинг, $ | B11: =SUM(C11:AL11) | C11: =IF(C9=1,MAX('Допущения'!$C$83,'Допущения'!$C$84*0)+IF(C6='Допущения'!$C$9,'Допущения'!$C$82,0),'Допущения'!$C$81) | D11: =IF(D9=1,MAX('Допущения'!$C$83,'Допущения'!$C$84*C28)+IF(D6='Допущения'!$C$9,'Допущения'!$C$82,0),'Допущения'!$C$81) | E11: =IF(E9=1,MAX('Допущения'!$C$83,'Допущения'!$C$84*D28)+IF(E6='Допущения'!$C$9,'Допущения'!$C$82,0),'Допущения'!$C$81) | F11: =IF(F9=1,MAX('Допущения'!$C$83,'Допущения'!$C$84*E28)+IF(F6='Допущения'!$C$9,'Допущения'!$C$82,0),'Допущения'!$C$81) | G11: =IF(G9=1,MAX('Допущения'!$C$83,'Допущения'!$C$84*F28)+IF(G6='Допущения'!$C$9,'Допущения'!$C$82,0),'Допущения'!$C$81) | H11: =IF(H9=1,MAX('Допущения'!$C$83,'Допущения'!$C$84*G28)+IF(H6='Допущения'!$C$9,'Допущения'!$C$82,0),'Допущения'!$C$81) | I11: =IF(I9=1,MAX('Допущения'!$C$83,'Допущения'!$C$84*H28)+IF(I6='Допущения'!$C$9,'Допущения'!$C$82,0),'Допущения'!$C$81) | J11: =IF(J9=1,MAX('Допущения'!$C$83,'Допущения'!$C$84*I28)+IF(J6='Допущения'!$C$9,'Допущения'!$C$82,0),'Допущения'!$C$81) | K11: =IF(K9=1,MAX('Допущения'!$C$83,'Допущения'!$C$84*J28)+IF(K6='Допущения'!$C$9,'Допущения'!$C$82,0),'Допущения'!$C$81) | ... AL11: =IF(AL9=1,MAX('Допущения'!$C$83,'Допущения'!$C$84*AK28)+IF(AL6='Допущения'!$C$9,'Допущения'!$C$82,0),'Допущения'!$C$81)
A12: Платные установки | B12: =SUM(C12:AL12) | C12: =IF(C9=1,C11/'Допущения'!$C$60,0) | D12: =IF(D9=1,D11/'Допущения'!$C$60,0) | E12: =IF(E9=1,E11/'Допущения'!$C$60,0) | F12: =IF(F9=1,F11/'Допущения'!$C$60,0) | G12: =IF(G9=1,G11/'Допущения'!$C$60,0) | H12: =IF(H9=1,H11/'Допущения'!$C$60,0) | I12: =IF(I9=1,I11/'Допущения'!$C$60,0) | J12: =IF(J9=1,J11/'Допущения'!$C$60,0) | ... AL12: =IF(AL9=1,AL11/'Допущения'!$C$60,0)
A13: Органические установки | B13: =SUM(C13:AL13) | C13: =IF(C9=1,MIN('Допущения'!$C$63,'Допущения'!$C$61*(1+'Допущения'!$C$62)^(C6-'Допущения'!$C$9)),0) | D13: =IF(D9=1,MIN('Допущения'!$C$63,'Допущения'!$C$61*(1+'Допущения'!$C$62)^(D6-'Допущения'!$C$9)),0) | E13: =IF(E9=1,MIN('Допущения'!$C$63,'Допущения'!$C$61*(1+'Допущения'!$C$62)^(E6-'Допущения'!$C$9)),0) | F13: =IF(F9=1,MIN('Допущения'!$C$63,'Допущения'!$C$61*(1+'Допущения'!$C$62)^(F6-'Допущения'!$C$9)),0) | G13: =IF(G9=1,MIN('Допущения'!$C$63,'Допущения'!$C$61*(1+'Допущения'!$C$62)^(G6-'Допущения'!$C$9)),0) | H13: =IF(H9=1,MIN('Допущения'!$C$63,'Допущения'!$C$61*(1+'Допущения'!$C$62)^(H6-'Допущения'!$C$9)),0) | I13: =IF(I9=1,MIN('Допущения'!$C$63,'Допущения'!$C$61*(1+'Допущения'!$C$62)^(I6-'Допущения'!$C$9)),0) | J13: =IF(J9=1,MIN('Допущения'!$C$63,'Допущения'!$C$61*(1+'Допущения'!$C$62)^(J6-'Допущения'!$C$9)),0) | ... AL13: =IF(AL9=1,MIN('Допущения'!$C$63,'Допущения'!$C$61*(1+'Допущения'!$C$62)^(AL6-'Допущения'!$C$9)),0)
A14: Вирусные установки | B14: =SUM(C14:AL14) | C14: =(C12+C13)*'Допущения'!$C$64 | D14: =(D12+D13)*'Допущения'!$C$64 | E14: =(E12+E13)*'Допущения'!$C$64 | F14: =(F12+F13)*'Допущения'!$C$64 | G14: =(G12+G13)*'Допущения'!$C$64 | H14: =(H12+H13)*'Допущения'!$C$64 | I14: =(I12+I13)*'Допущения'!$C$64 | J14: =(J12+J13)*'Допущения'!$C$64 | ... AL14: =(AL12+AL13)*'Допущения'!$C$64
A15: Всего установок | B15: =SUM(C15:AL15) | C15: =C12+C13+C14 | D15: =D12+D13+D14 | E15: =E12+E13+E14 | F15: =F12+F13+F14 | G15: =G12+G13+G14 | H15: =H12+H13+H14 | I15: =I12+I13+I14 | J15: =J12+J13+J14 | ... AL15: =AL12+AL13+AL14
A16: Новые активированные | B16: =SUM(C16:AL16) | C16: =C15*'Допущения'!$C$65+IF(C6='Допущения'!$C$9,0*'Допущения'!$C$78,0) | D16: =D15*'Допущения'!$C$65+IF(D6='Допущения'!$C$9,C17*'Допущения'!$C$78,0) | E16: =E15*'Допущения'!$C$65+IF(E6='Допущения'!$C$9,D17*'Допущения'!$C$78,0) | F16: =F15*'Допущения'!$C$65+IF(F6='Допущения'!$C$9,E17*'Допущения'!$C$78,0) | G16: =G15*'Допущения'!$C$65+IF(G6='Допущения'!$C$9,F17*'Допущения'!$C$78,0) | H16: =H15*'Допущения'!$C$65+IF(H6='Допущения'!$C$9,G17*'Допущения'!$C$78,0) | I16: =I15*'Допущения'!$C$65+IF(I6='Допущения'!$C$9,H17*'Допущения'!$C$78,0) | J16: =J15*'Допущения'!$C$65+IF(J6='Допущения'!$C$9,I17*'Допущения'!$C$78,0) | K16: =K15*'Допущения'!$C$65+IF(K6='Допущения'!$C$9,J17*'Допущения'!$C$78,0) | ... AL16: =AL15*'Допущения'!$C$65+IF(AL6='Допущения'!$C$9,AK17*'Допущения'!$C$78,0)
A17: Игроки прототипа (до выхода) | C17: =IF(C9=1,0,'Допущения'!$C$72*(1+'Допущения'!$C$73)^(C6-1)) | D17: =IF(D9=1,0,'Допущения'!$C$72*(1+'Допущения'!$C$73)^(D6-1)) | E17: =IF(E9=1,0,'Допущения'!$C$72*(1+'Допущения'!$C$73)^(E6-1)) | F17: =IF(F9=1,0,'Допущения'!$C$72*(1+'Допущения'!$C$73)^(F6-1)) | G17: =IF(G9=1,0,'Допущения'!$C$72*(1+'Допущения'!$C$73)^(G6-1)) | H17: =IF(H9=1,0,'Допущения'!$C$72*(1+'Допущения'!$C$73)^(H6-1)) | I17: =IF(I9=1,0,'Допущения'!$C$72*(1+'Допущения'!$C$73)^(I6-1)) | J17: =IF(J9=1,0,'Допущения'!$C$72*(1+'Допущения'!$C$73)^(J6-1)) | ... AL17: =IF(AL9=1,0,'Допущения'!$C$72*(1+'Допущения'!$C$73)^(AL6-1))
A18: Активные free (на конец мес.) | C18: =IF(C9=1,0*(1-'Допущения'!$C$68)*'Допущения'!$C$66+C16*(1-'Допущения'!$C$67),0) | D18: =IF(D9=1,C18*(1-'Допущения'!$C$68)*'Допущения'!$C$66+D16*(1-'Допущения'!$C$67),0) | E18: =IF(E9=1,D18*(1-'Допущения'!$C$68)*'Допущения'!$C$66+E16*(1-'Допущения'!$C$67),0) | F18: =IF(F9=1,E18*(1-'Допущения'!$C$68)*'Допущения'!$C$66+F16*(1-'Допущения'!$C$67),0) | G18: =IF(G9=1,F18*(1-'Допущения'!$C$68)*'Допущения'!$C$66+G16*(1-'Допущения'!$C$67),0) | H18: =IF(H9=1,G18*(1-'Допущения'!$C$68)*'Допущения'!$C$66+H16*(1-'Допущения'!$C$67),0) | I18: =IF(I9=1,H18*(1-'Допущения'!$C$68)*'Допущения'!$C$66+I16*(1-'Допущения'!$C$67),0) | J18: =IF(J9=1,I18*(1-'Допущения'!$C$68)*'Допущения'!$C$66+J16*(1-'Допущения'!$C$67),0) | K18: =IF(K9=1,J18*(1-'Допущения'!$C$68)*'Допущения'!$C$66+K16*(1-'Допущения'!$C$67),0) | ... AL18: =IF(AL9=1,AK18*(1-'Допущения'!$C$68)*'Допущения'!$C$66+AL16*(1-'Допущения'!$C$67),0)
A19: Новые платящие | B19: =SUM(C19:AL19) | C19: =IF(C9=1,C16*'Допущения'!$C$67+0*'Допущения'!$C$68,0) | D19: =IF(D9=1,D16*'Допущения'!$C$67+C18*'Допущения'!$C$68,0) | E19: =IF(E9=1,E16*'Допущения'!$C$67+D18*'Допущения'!$C$68,0) | F19: =IF(F9=1,F16*'Допущения'!$C$67+E18*'Допущения'!$C$68,0) | G19: =IF(G9=1,G16*'Допущения'!$C$67+F18*'Допущения'!$C$68,0) | H19: =IF(H9=1,H16*'Допущения'!$C$67+G18*'Допущения'!$C$68,0) | I19: =IF(I9=1,I16*'Допущения'!$C$67+H18*'Допущения'!$C$68,0) | J19: =IF(J9=1,J16*'Допущения'!$C$67+I18*'Допущения'!$C$68,0) | K19: =IF(K9=1,K16*'Допущения'!$C$67+J18*'Допущения'!$C$68,0) | ... AL19: =IF(AL9=1,AL16*'Допущения'!$C$67+AK18*'Допущения'!$C$68,0)
A20: Ушедшие платящие | B20: =SUM(C20:AL20) | C20: =0*'Допущения'!$C$69 | D20: =C21*'Допущения'!$C$69 | E20: =D21*'Допущения'!$C$69 | F20: =E21*'Допущения'!$C$69 | G20: =F21*'Допущения'!$C$69 | H20: =G21*'Допущения'!$C$69 | I20: =H21*'Допущения'!$C$69 | J20: =I21*'Допущения'!$C$69 | K20: =J21*'Допущения'!$C$69 | ... AL20: =AK21*'Допущения'!$C$69
A21: Платящие (на конец мес.) | C21: =0+C19-C20 | D21: =C21+D19-D20 | E21: =D21+E19-E20 | F21: =E21+F19-F20 | G21: =F21+G19-G20 | H21: =G21+H19-H20 | I21: =H21+I19-I20 | J21: =I21+J19-J20 | K21: =J21+K19-K20 | ... AL21: =AK21+AL19-AL20
A22: Активные пользователи всего | C22: =C17+C18+C21 | D22: =D17+D18+D21 | E22: =E17+E18+E21 | F22: =F17+F18+F21 | G22: =G17+G18+G21 | H22: =H17+H18+H21 | I22: =I17+I18+I21 | J22: =J17+J18+J21 | ... AL22: =AL17+AL18+AL21
A23: ВЫРУЧКА, $
A24: Оплаты подписок (брутто) | B24: =SUM(C24:AL24) | C24: =C21*'Себестоимость'!$C$12 | D24: =D21*'Себестоимость'!$C$12 | E24: =E21*'Себестоимость'!$C$12 | F24: =F21*'Себестоимость'!$C$12 | G24: =G21*'Себестоимость'!$C$12 | H24: =H21*'Себестоимость'!$C$12 | I24: =I21*'Себестоимость'!$C$12 | J24: =J21*'Себестоимость'!$C$12 | ... AL24: =AL21*'Себестоимость'!$C$12
A25: Комиссии магазинов/Paddle и НДС | B25: =SUM(C25:AL25) | C25: =C24-C26 | D25: =D24-D26 | E25: =E24-E26 | F25: =F24-F26 | G25: =G24-G26 | H25: =H24-H26 | I25: =I24-I26 | J25: =J24-J26 | ... AL25: =AL24-AL26
A26: Чистая выручка подписок | B26: =SUM(C26:AL26) | C26: =C21*'Себестоимость'!$C$13 | D26: =D21*'Себестоимость'!$C$13 | E26: =E21*'Себестоимость'!$C$13 | F26: =F21*'Себестоимость'!$C$13 | G26: =G21*'Себестоимость'!$C$13 | H26: =H21*'Себестоимость'!$C$13 | I26: =I21*'Себестоимость'!$C$13 | J26: =J21*'Себестоимость'!$C$13 | ... AL26: =AL21*'Себестоимость'!$C$13
A27: Донаты (чистые) | B27: =SUM(C27:AL27) | C27: =C17*'Допущения'!$C$75*'Допущения'!$C$76*(1-'Допущения'!$C$77) | D27: =D17*'Допущения'!$C$75*'Допущения'!$C$76*(1-'Допущения'!$C$77) | E27: =E17*'Допущения'!$C$75*'Допущения'!$C$76*(1-'Допущения'!$C$77) | F27: =F17*'Допущения'!$C$75*'Допущения'!$C$76*(1-'Допущения'!$C$77) | G27: =G17*'Допущения'!$C$75*'Допущения'!$C$76*(1-'Допущения'!$C$77) | H27: =H17*'Допущения'!$C$75*'Допущения'!$C$76*(1-'Допущения'!$C$77) | I27: =I17*'Допущения'!$C$75*'Допущения'!$C$76*(1-'Допущения'!$C$77) | J27: =J17*'Допущения'!$C$75*'Допущения'!$C$76*(1-'Допущения'!$C$77) | ... AL27: =AL17*'Допущения'!$C$75*'Допущения'!$C$76*(1-'Допущения'!$C$77)
A28: Итого чистая выручка | B28: =SUM(C28:AL28) | C28: =C26+C27 | D28: =D26+D27 | E28: =E26+E27 | F28: =F26+F27 | G28: =G26+G27 | H28: =H26+H27 | I28: =I26+I27 | J28: =J26+J27 | ... AL28: =AL26+AL27
A29: ПЕРЕМЕННЫЕ ЗАТРАТЫ, $
A30: LLM: платящие | B30: =SUM(C30:AL30) | C30: =C21*'Себестоимость'!$C$14 | D30: =D21*'Себестоимость'!$C$14 | E30: =E21*'Себестоимость'!$C$14 | F30: =F21*'Себестоимость'!$C$14 | G30: =G21*'Себестоимость'!$C$14 | H30: =H21*'Себестоимость'!$C$14 | I30: =I21*'Себестоимость'!$C$14 | J30: =J21*'Себестоимость'!$C$14 | ... AL30: =AL21*'Себестоимость'!$C$14
A31: LLM: free и прототип | B31: =SUM(C31:AL31) | C31: =C18*'Себестоимость'!$C$16+C17*'Допущения'!$C$74*'Себестоимость'!$C$7 | D31: =D18*'Себестоимость'!$C$16+D17*'Допущения'!$C$74*'Себестоимость'!$C$7 | E31: =E18*'Себестоимость'!$C$16+E17*'Допущения'!$C$74*'Себестоимость'!$C$7 | F31: =F18*'Себестоимость'!$C$16+F17*'Допущения'!$C$74*'Себестоимость'!$C$7 | G31: =G18*'Себестоимость'!$C$16+G17*'Допущения'!$C$74*'Себестоимость'!$C$7 | H31: =H18*'Себестоимость'!$C$16+H17*'Допущения'!$C$74*'Себестоимость'!$C$7 | I31: =I18*'Себестоимость'!$C$16+I17*'Допущения'!$C$74*'Себестоимость'!$C$7 | J31: =J18*'Себестоимость'!$C$16+J17*'Допущения'!$C$74*'Себестоимость'!$C$7 | ... AL31: =AL18*'Себестоимость'!$C$16+AL17*'Допущения'!$C$74*'Себестоимость'!$C$7
A32: Проверка возраста | B32: =SUM(C32:AL32) | C32: =C19*'Допущения'!$C$44*'Допущения'!$C$93 | D32: =D19*'Допущения'!$C$44*'Допущения'!$C$93 | E32: =E19*'Допущения'!$C$44*'Допущения'!$C$93 | F32: =F19*'Допущения'!$C$44*'Допущения'!$C$93 | G32: =G19*'Допущения'!$C$44*'Допущения'!$C$93 | H32: =H19*'Допущения'!$C$44*'Допущения'!$C$93 | I32: =I19*'Допущения'!$C$44*'Допущения'!$C$93 | J32: =J19*'Допущения'!$C$44*'Допущения'!$C$93 | ... AL32: =AL19*'Допущения'!$C$44*'Допущения'!$C$93
A33: Инфраструктура (на пользователя) | B33: =SUM(C33:AL33) | C33: =C22*'Допущения'!$C$86 | D33: =D22*'Допущения'!$C$86 | E33: =E22*'Допущения'!$C$86 | F33: =F22*'Допущения'!$C$86 | G33: =G22*'Допущения'!$C$86 | H33: =H22*'Допущения'!$C$86 | I33: =I22*'Допущения'!$C$86 | J33: =J22*'Допущения'!$C$86 | ... AL33: =AL22*'Допущения'!$C$86
A34: Итого переменные | B34: =SUM(C34:AL34) | C34: =SUM(C30:C33) | D34: =SUM(D30:D33) | E34: =SUM(E30:E33) | F34: =SUM(F30:F33) | G34: =SUM(G30:G33) | H34: =SUM(H30:H33) | I34: =SUM(I30:I33) | J34: =SUM(J30:J33) | ... AL34: =SUM(AL30:AL33)
A35: Валовая прибыль | B35: =SUM(C35:AL35) | C35: =C28-C34 | D35: =D28-D34 | E35: =E28-E34 | F35: =F28-F34 | G35: =G28-G34 | H35: =H28-H34 | I35: =I28-I34 | J35: =J28-J34 | ... AL35: =AL28-AL34
A36: Валовая маржа | B36: =IFERROR(B35/B28,0) | C36: =IFERROR(C35/C28,0) | D36: =IFERROR(D35/D28,0) | E36: =IFERROR(E35/E28,0) | F36: =IFERROR(F35/F28,0) | G36: =IFERROR(G35/G28,0) | H36: =IFERROR(H35/H28,0) | I36: =IFERROR(I35/I28,0) | ... AL36: =IFERROR(AL35/AL28,0)
A37: ПОСТОЯННЫЕ ЗАТРАТЫ И МАРКЕТИНГ, $
A38: Инфраструктура (база) | B38: =SUM(C38:AL38) | C38: ='Допущения'!$C$85 | D38: ='Допущения'!$C$85 | E38: ='Допущения'!$C$85 | F38: ='Допущения'!$C$85 | G38: ='Допущения'!$C$85 | H38: ='Допущения'!$C$85 | I38: ='Допущения'!$C$85 | J38: ='Допущения'!$C$85 | ... AL38: ='Допущения'!$C$85
A39: SaaS-инструменты | B39: =SUM(C39:AL39) | C39: ='Допущения'!$C$87 | D39: ='Допущения'!$C$87 | E39: ='Допущения'!$C$87 | F39: ='Допущения'!$C$87 | G39: ='Допущения'!$C$87 | H39: ='Допущения'!$C$87 | I39: ='Допущения'!$C$87 | J39: ='Допущения'!$C$87 | ... AL39: ='Допущения'!$C$87
A40: Бухгалтерия | B40: =SUM(C40:AL40) | C40: =IF(C6>='Допущения'!$C$10,'Допущения'!$C$88,0) | D40: =IF(D6>='Допущения'!$C$10,'Допущения'!$C$88,0) | E40: =IF(E6>='Допущения'!$C$10,'Допущения'!$C$88,0) | F40: =IF(F6>='Допущения'!$C$10,'Допущения'!$C$88,0) | G40: =IF(G6>='Допущения'!$C$10,'Допущения'!$C$88,0) | H40: =IF(H6>='Допущения'!$C$10,'Допущения'!$C$88,0) | I40: =IF(I6>='Допущения'!$C$10,'Допущения'!$C$88,0) | J40: =IF(J6>='Допущения'!$C$10,'Допущения'!$C$88,0) | ... AL40: =IF(AL6>='Допущения'!$C$10,'Допущения'!$C$88,0)
A41: Юр. сопровождение | B41: =SUM(C41:AL41) | C41: =IF(C9=1,'Допущения'!$C$89,0) | D41: =IF(D9=1,'Допущения'!$C$89,0) | E41: =IF(E9=1,'Допущения'!$C$89,0) | F41: =IF(F9=1,'Допущения'!$C$89,0) | G41: =IF(G9=1,'Допущения'!$C$89,0) | H41: =IF(H9=1,'Допущения'!$C$89,0) | I41: =IF(I9=1,'Допущения'!$C$89,0) | J41: =IF(J9=1,'Допущения'!$C$89,0) | ... AL41: =IF(AL9=1,'Допущения'!$C$89,0)
A42: Магазины приложений | B42: =SUM(C42:AL42) | C42: =IF(C6='Допущения'!$C$9-1,'Допущения'!$C$90+'Допущения'!$C$91,0)+IF(AND(C6>'Допущения'!$C$9-1,MOD(C6-('Допущения'!$C$9-1),12)=0),'Допущения'!$C$90,0) | D42: =IF(D6='Допущения'!$C$9-1,'Допущения'!$C$90+'Допущения'!$C$91,0)+IF(AND(D6>'Допущения'!$C$9-1,MOD(D6-('Допущения'!$C$9-1),12)=0),'Допущения'!$C$90,0) | E42: =IF(E6='Допущения'!$C$9-1,'Допущения'!$C$90+'Допущения'!$C$91,0)+IF(AND(E6>'Допущения'!$C$9-1,MOD(E6-('Допущения'!$C$9-1),12)=0),'Допущения'!$C$90,0) | F42: =IF(F6='Допущения'!$C$9-1,'Допущения'!$C$90+'Допущения'!$C$91,0)+IF(AND(F6>'Допущения'!$C$9-1,MOD(F6-('Допущения'!$C$9-1),12)=0),'Допущения'!$C$90,0) | G42: =IF(G6='Допущения'!$C$9-1,'Допущения'!$C$90+'Допущения'!$C$91,0)+IF(AND(G6>'Допущения'!$C$9-1,MOD(G6-('Допущения'!$C$9-1),12)=0),'Допущения'!$C$90,0) | H42: =IF(H6='Допущения'!$C$9-1,'Допущения'!$C$90+'Допущения'!$C$91,0)+IF(AND(H6>'Допущения'!$C$9-1,MOD(H6-('Допущения'!$C$9-1),12)=0),'Допущения'!$C$90,0) | I42: =IF(I6='Допущения'!$C$9-1,'Допущения'!$C$90+'Допущения'!$C$91,0)+IF(AND(I6>'Допущения'!$C$9-1,MOD(I6-('Допущения'!$C$9-1),12)=0),'Допущения'!$C$90,0) | J42: =IF(J6='Допущения'!$C$9-1,'Допущения'!$C$90+'Допущения'!$C$91,0)+IF(AND(J6>'Допущения'!$C$9-1,MOD(J6-('Допущения'!$C$9-1),12)=0),'Допущения'!$C$90,0) | ... AL42: =IF(AL6='Допущения'!$C$9-1,'Допущения'!$C$90+'Допущения'!$C$91,0)+IF(AND(AL6>'Допущения'!$C$9-1,MOD(AL6-('Допущения'!$C$9-1),12)=0),'Допущения'!$C$90,0)
...

Sheet Модель_О
A1: Финмодель на 36 месяцев — сценарий: Оптимистичный
A2: Все значения считаются формулами из листов «Допущения», «Себестоимость», «Старт».
B5: Итого / знач.
A6: Месяц № | C6: 1 | D6: 2 | E6: 3 | F6: 4 | G6: 5 | H6: 6 | I6: 7 | J6: 8 | K6: 9 | L6: 10 | M6: 11 | N6: 12 | O6: 13 | P6: 14 | Q6: 15 | R6: 16 | S6: 17 | T6: 18 | U6: 19 | V6: 20 | W6: 21 | X6: 22 | Y6: 23 | Z6: 24 | AA6: 25 | AB6: 26 | AC6: 27 | AD6: 28 | AE6: 29 | AF6: 30 | AG6: 31 | AH6: 32 | AI6: 33 | AJ6: 34 | AK6: 35 | AL6: 36
A7: Месяц | C7: ноя 2026 | D7: дек 2026 | E7: янв 2027 | F7: фев 2027 | G7: мар 2027 | H7: апр 2027 | I7: май 2027 | J7: июн 2027 | K7: июл 2027 | L7: авг 2027 | M7: сен 2027 | N7: окт 2027 | O7: ноя 2027 | P7: дек 2027 | Q7: янв 2028 | R7: фев 2028 | S7: мар 2028 | T7: апр 2028 | U7: май 2028 | V7: июн 2028 | W7: июл 2028 | X7: авг 2028 | Y7: сен 2028 | Z7: окт 2028 | AA7: ноя 2028 | AB7: дек 2028 | AC7: янв 2029 | AD7: фев 2029 | AE7: мар 2029 | AF7: апр 2029 | AG7: май 2029 | AH7: июн 2029 | AI7: июл 2029 | AJ7: авг 2029 | AK7: сен 2029 | AL7: окт 2029
A8: Год проекта | C8: 1 | D8: 1 | E8: 1 | F8: 1 | G8: 1 | H8: 1 | I8: 1 | J8: 1 | K8: 1 | L8: 1 | M8: 1 | N8: 1 | O8: 2 | P8: 2 | Q8: 2 | R8: 2 | S8: 2 | T8: 2 | U8: 2 | V8: 2 | W8: 2 | X8: 2 | Y8: 2 | Z8: 2 | AA8: 3 | AB8: 3 | AC8: 3 | AD8: 3 | AE8: 3 | AF8: 3 | AG8: 3 | AH8: 3 | AI8: 3 | AJ8: 3 | AK8: 3 | AL8: 3
A9: Рынок (1 = MVP вышел) | C9: =IF(C6>='Допущения'!$E$9,1,0) | D9: =IF(D6>='Допущения'!$E$9,1,0) | E9: =IF(E6>='Допущения'!$E$9,1,0) | F9: =IF(F6>='Допущения'!$E$9,1,0) | G9: =IF(G6>='Допущения'!$E$9,1,0) | H9: =IF(H6>='Допущения'!$E$9,1,0) | I9: =IF(I6>='Допущения'!$E$9,1,0) | J9: =IF(J6>='Допущения'!$E$9,1,0) | ... AL9: =IF(AL6>='Допущения'!$E$9,1,0)
A10: ВОРОНКА
A11: Маркетинг, $ | B11: =SUM(C11:AL11) | C11: =IF(C9=1,MAX('Допущения'!$E$83,'Допущения'!$E$84*0)+IF(C6='Допущения'!$E$9,'Допущения'!$E$82,0),'Допущения'!$E$81) | D11: =IF(D9=1,MAX('Допущения'!$E$83,'Допущения'!$E$84*C28)+IF(D6='Допущения'!$E$9,'Допущения'!$E$82,0),'Допущения'!$E$81) | E11: =IF(E9=1,MAX('Допущения'!$E$83,'Допущения'!$E$84*D28)+IF(E6='Допущения'!$E$9,'Допущения'!$E$82,0),'Допущения'!$E$81) | F11: =IF(F9=1,MAX('Допущения'!$E$83,'Допущения'!$E$84*E28)+IF(F6='Допущения'!$E$9,'Допущения'!$E$82,0),'Допущения'!$E$81) | G11: =IF(G9=1,MAX('Допущения'!$E$83,'Допущения'!$E$84*F28)+IF(G6='Допущения'!$E$9,'Допущения'!$E$82,0),'Допущения'!$E$81) | H11: =IF(H9=1,MAX('Допущения'!$E$83,'Допущения'!$E$84*G28)+IF(H6='Допущения'!$E$9,'Допущения'!$E$82,0),'Допущения'!$E$81) | I11: =IF(I9=1,MAX('Допущения'!$E$83,'Допущения'!$E$84*H28)+IF(I6='Допущения'!$E$9,'Допущения'!$E$82,0),'Допущения'!$E$81) | J11: =IF(J9=1,MAX('Допущения'!$E$83,'Допущения'!$E$84*I28)+IF(J6='Допущения'!$E$9,'Допущения'!$E$82,0),'Допущения'!$E$81) | K11: =IF(K9=1,MAX('Допущения'!$E$83,'Допущения'!$E$84*J28)+IF(K6='Допущения'!$E$9,'Допущения'!$E$82,0),'Допущения'!$E$81) | ... AL11: =IF(AL9=1,MAX('Допущения'!$E$83,'Допущения'!$E$84*AK28)+IF(AL6='Допущения'!$E$9,'Допущения'!$E$82,0),'Допущения'!$E$81)
A12: Платные установки | B12: =SUM(C12:AL12) | C12: =IF(C9=1,C11/'Допущения'!$E$60,0) | D12: =IF(D9=1,D11/'Допущения'!$E$60,0) | E12: =IF(E9=1,E11/'Допущения'!$E$60,0) | F12: =IF(F9=1,F11/'Допущения'!$E$60,0) | G12: =IF(G9=1,G11/'Допущения'!$E$60,0) | H12: =IF(H9=1,H11/'Допущения'!$E$60,0) | I12: =IF(I9=1,I11/'Допущения'!$E$60,0) | J12: =IF(J9=1,J11/'Допущения'!$E$60,0) | ... AL12: =IF(AL9=1,AL11/'Допущения'!$E$60,0)
A13: Органические установки | B13: =SUM(C13:AL13) | C13: =IF(C9=1,MIN('Допущения'!$E$63,'Допущения'!$E$61*(1+'Допущения'!$E$62)^(C6-'Допущения'!$E$9)),0) | D13: =IF(D9=1,MIN('Допущения'!$E$63,'Допущения'!$E$61*(1+'Допущения'!$E$62)^(D6-'Допущения'!$E$9)),0) | E13: =IF(E9=1,MIN('Допущения'!$E$63,'Допущения'!$E$61*(1+'Допущения'!$E$62)^(E6-'Допущения'!$E$9)),0) | F13: =IF(F9=1,MIN('Допущения'!$E$63,'Допущения'!$E$61*(1+'Допущения'!$E$62)^(F6-'Допущения'!$E$9)),0) | G13: =IF(G9=1,MIN('Допущения'!$E$63,'Допущения'!$E$61*(1+'Допущения'!$E$62)^(G6-'Допущения'!$E$9)),0) | H13: =IF(H9=1,MIN('Допущения'!$E$63,'Допущения'!$E$61*(1+'Допущения'!$E$62)^(H6-'Допущения'!$E$9)),0) | I13: =IF(I9=1,MIN('Допущения'!$E$63,'Допущения'!$E$61*(1+'Допущения'!$E$62)^(I6-'Допущения'!$E$9)),0) | J13: =IF(J9=1,MIN('Допущения'!$E$63,'Допущения'!$E$61*(1+'Допущения'!$E$62)^(J6-'Допущения'!$E$9)),0) | ... AL13: =IF(AL9=1,MIN('Допущения'!$E$63,'Допущения'!$E$61*(1+'Допущения'!$E$62)^(AL6-'Допущения'!$E$9)),0)
